Workbook

Sheet FBA FEES
C1: Size Tire | D1: Additional Fees Per LB
C2: 3 to 20 (LB) | D2: 0.32 | I2: 15.1 | K2: Weight | L2: Shipping weight/Size tier | M2: Large bulky | N2: Extra-large 0 to 50 lb | O2: Extra-large 50+ to 70 lb | P2: Extra-large 70+ to 150 lb | Q2: Extra-large 150+ lb | S2: Tier
K3: LB | L3: OZ | M3: DIMS-59*33*33 Girth - 130 | N3: 59+*33+*33+ Girth - 130 | O3: 59+*33+*33+ Girth - 130 | P3: 59+*33+*33+ Girth - 130 | Q3: 59+*33+*33+ Girth - 130 | S3: =IF(AND($I$12<=P44,$D$8<=M44,$D$9<=N44,$D$10<=O44),K44,IF(AND($I$12<=P45,$D$8<=M45,$D$9<=N45,$D$10<=O45),K45,IF(AND($D$8<=M46,$D$9<=N46,$D$10<=O46,$I$12<=P46),K46,IF(AND($I$12<=P47,OR(N$8>M47,$D$9>N47,$D$10>O47)),K47,IF(AND($I$12>P47,$I$12<=P48),K48,IF(AND($I$12>P48,$I$12<=P49),K49,K50)))))) -> 47
K4: 1 | L4: =K4*16 -> 16 | M4: 9.61 | N4: 26.33 | S4: Fees
K5: 2 | L5: =K5*16 -> 32 | M5: =$I$10+(K4*$I$18) -> 9.99 | N5: =$I$11+(K4*$I$18) -> 26.71 | S5: =IFERROR(VLOOKUP(ROUNDUP($D$7,0),'FBA FEES'!$L$2:$Q$203,MATCH(S3,'FBA FEES'!$L$2:$Q$2,0),FALSE),VLOOKUP(ROUNDUP($D$7,0),'FBA FEES'!$C$6:$F$123,MATCH(S3,'FBA FEES'!$C$6:$F$6,0),FALSE)) -> #VALUE!
B6: Weight | C6: Shipping weight/Size tier | D6: Small standard-size | E6: Large standard | F6: Large standard-size | K6: 3 | L6: =K6*16 -> 48 | M6: =$I$10+(K5*$I$18) -> 10.37 | N6: =$I$11+(K5*$I$18) -> 27.09 | S6: =ROUND(MAX($D$11,$D$12),0) -> 3
A7: SR.NO | B7: LB | C7: OZ | D7: 15*12*0.75 (16 oz) | E7: 18*14*8 (20 LB) | F7: Final Fees Charged | K7: 4 | L7: =K7*16 -> 64 | M7: =$I$10+(K6*$I$18) -> 10.75 | N7: =$I$11+(K6*$I$18) -> 27.47
A8: =ROUND(B8,2) -> 0.04 | B8: 0.04 | C8: 1 | D8: 3.06 | E8: 3.68 | F8: =IF(B8<=3,E8,IF(B8<=20,E8+((B8-3)*$D$2),)) -> 3.68 | K8: 5 | L8: =K8*16 -> 80 | M8: =$I$10+(K7*$I$18) -> 11.13 | N8: =$I$11+(K7*$I$18) -> 27.85
A9: =ROUND(B9,2) -> 0.13 | B9: 0.125 | C9: 2 | D9: 3.06 | E9: 3.68 | F9: =IF(B9<=3,E9,IF(B9<=20,E9+((B9-3)*$D$2),)) -> 3.68 | G9: Additional fee applicable | H9: Size Tire | I9: Fixed FBA Fees | K9: 6 | L9: =K9*16 -> 96 | M9: =$I$10+(K8*$I$18) -> 11.51 | N9: =$I$11+(K8*$I$18) -> 28.23
A10: =ROUND(B10,2) -> 0.19 | B10: 0.1875 | C10: 3 | D10: 3.15 | E10: 3.68 | F10: =IF(B10<=3,E10,IF(B10<=20,E10+((B10-3)*$D$2),)) -> 3.68 | G10: above first lb | H10: Large Bulky | I10: 9.61 | K10: 7 | L10: =K10*16 -> 112 | M10: =$I$10+(K9*$I$18) -> 11.89 | N10: =$I$11+(K9*$I$18) -> 28.61
A11: =ROUND(B11,2) -> 0.25 | B11: 0.25 | C11: 4 | D11: 3.15 | E11: 3.68 | F11: =IF(B11<=3,E11,IF(B11<=20,E11+((B11-3)*$D$2),)) -> 3.68 | G11: above first lb | H11: Extra-large 0 to 50 lb | I11: 26.33 | K11: 8 | L11: =K11*16 -> 128 | M11: =$I$10+(K10*$I$18) -> 12.27 | N11: =$I$11+(K10*$I$18) -> 28.99
A12: =ROUND(B12,2) -> 0.31 | B12: 0.3125 | C12: 5 | D12: 3.24 | E12: 3.9 | F12: =IF(B12<=3,E12,IF(B12<=20,E12+((B12-3)*$D$2),)) -> 3.9 | G12: above 51 lb | H12: Extra-large 50 to 70 lb | I12: 40.12 | K12: 9 | L12: =K12*16 -> 144 | M12: =$I$10+(K11*$I$18) -> 12.65 | N12: =$I$11+(K11*$I$18) -> 29.37
A13: =ROUND(B13,2) -> 0.38 | B13: 0.375 | C13: 6 | D13: 3.24 | E13: 3.9 | F13: =IF(B13<=3,E13,IF(B13<=20,E13+((B13-3)*$D$2),)) -> 3.9 | G13: above 71 lb | H13: Extra-large 70 to 150 lb | I13: 54.81 | K13: 10 | L13: =K13*16 -> 160 | M13: =$I$10+(K12*$I$18) -> 13.03 | N13: =$I$11+(K12*$I$18) -> 29.75
A14: =ROUND(B14,2) -> 0.44 | B14: 0.4375 | C14: 7 | D14: 3.33 | E14: 3.9 | F14: =IF(B14<=3,E14,IF(B14<=20,E14+((B14-3)*$D$2),)) -> 3.9 | G14: above 151 lb | H14: Extra-large 150+++ lb | I14: 194.95 | K14: 11 | L14: =K14*16 -> 176 | M14: =$I$10+(K13*$I$18) -> 13.41 | N14: =$I$11+(K13*$I$18) -> 30.13
A15: =ROUND(B15,2) -> 0.5 | B15: 0.5 | C15: 8 | D15: 3.33 | E15: 3.9 | F15: =IF(B15<=3,E15,IF(B15<=20,E15+((B15-3)*$D$2),)) -> 3.9 | K15: 12 | L15: =K15*16 -> 192 | M15: =$I$10+(K14*$I$18) -> 13.79 | N15: =$I$11+(K14*$I$18) -> 30.51
A16: =ROUND(B16,2) -> 0.56 | B16: 0.5625 | C16: 9 | D16: 3.43 | E16: 4.15 | F16: =IF(B16<=3,E16,IF(B16<=20,E16+((B16-3)*$D$2),)) -> 4.15 | K16: 13 | L16: =K16*16 -> 208 | M16: =$I$10+(K15*$I$18) -> 14.17 | N16: =$I$11+(K15*$I$18) -> 30.89
A17: =ROUND(B17,2) -> 0.63 | B17: 0.625 | C17: 10 | D17: 3.43 | E17: 4.15 | F17: =IF(B17<=3,E17,IF(B17<=20,E17+((B17-3)*$D$2),)) -> 4.15 | H17: Size Tire | I17: Additional Fees Per LB | K17: 14 | L17: =K17*16 -> 224 | M17: =$I$10+(K16*$I$18) -> 14.55 | N17: =$I$11+(K16*$I$18) -> 31.27
A18: =ROUND(B18,2) -> 0.69 | B18: 0.6875 | C18: 11 | D18: 3.53 | E18: 4.15 | F18: =IF(B18<=3,E18,IF(B18<=20,E18+((B18-3)*$D$2),)) -> 4.15 | H18: 0 to 50 (LB) | I18: 0.38 | K18: 15 | L18: =K18*16 -> 240 | M18: =$I$10+(K17*$I$18) -> 14.93 | N18: =$I$11+(K17*$I$18) -> 31.65
A19: =ROUND(B19,2) -> 0.75 | B19: 0.75 | C19: 12 | D19: 3.53 | E19: 4.15 | F19: =IF(B19<=3,E19,IF(B19<=20,E19+((B19-3)*$D$2),)) -> 4.15 | H19: 50 to 150 (LB) | I19: 0.75 | K19: 16 | L19: =K19*16 -> 256 | M19: =$I$10+(K18*$I$18) -> 15.31 | N19: =$I$11+(K18*$I$18) -> 32.03
A20: =ROUND(B20,2) -> 0.81 | B20: 0.8125 | C20: 13 | D20: 3.6 | E20: 4.55 | F20: =IF(B20<=3,E20,IF(B20<=20,E20+((B20-3)*$D$2),)) -> 4.55 | H20: 150+++ (LB) | I20: 0.19 | K20: 17 | L20: =K20*16 -> 272 | M20: =$I$10+(K19*$I$18) -> 15.69 | N20: =$I$11+(K19*$I$18) -> 32.41
A21: =ROUND(B21,2) -> 0.88 | B21: 0.875 | C21: 14 | D21: 3.6 | E21: 4.55 | F21: =IF(B21<=3,E21,IF(B21<=20,E21+((B21-3)*$D$2),)) -> 4.55 | K21: 18 | L21: =K21*16 -> 288 | M21: =$I$10+(K20*$I$18) -> 16.07 | N21: =$I$11+(K20*$I$18) -> 32.79
A22: =ROUND(B22,2) -> 0.94 | B22: 0.9375 | C22: 15 | D22: 3.65 | E22: 4.55 | F22: =IF(B22<=3,E22,IF(B22<=20,E22+((B22-3)*$D$2),)) -> 4.55 | K22: 19 | L22: =K22*16 -> 304 | M22: =$I$10+(K21*$I$18) -> 16.45 | N22: =$I$11+(K21*$I$18) -> 33.17
A23: =ROUND(B23,2) -> 1 | B23: 1 | C23: 16 | D23: 3.65 | E23: 4.55 | F23: =IF(B23<=3,E23,IF(B23<=20,E23+((B23-3)*$D$2),)) -> 4.55 | K23: 20 | L23: =K23*16 -> 320 | M23: =$I$10+(K22*$I$18) -> 16.83 | N23: =$I$11+(K22*$I$18) -> 33.55
A24: =ROUND(B24,2) -> 1.06 | B24: 1.0625 | C24: 17 | E24: 4.99 | F24: =IF(B24<=3,E24,IF(B24<=20,E24+((B24-3)*$D$2),)) -> 4.99 | K24: 21 | L24: =K24*16 -> 336 | M24: =$I$10+(K23*$I$18) -> 17.21 | N24: =$I$11+(K23*$I$18) -> 33.93
A25: =ROUND(B25,2) -> 1.13 | B25: 1.125 | C25: 18 | E25: 4.99 | F25: =IF(B25<=3,E25,IF(B25<=20,E25+((B25-3)*$D$2),)) -> 4.99 | K25: 22 | L25: =K25*16 -> 352 | M25: =$I$10+(K24*$I$18) -> 17.59 | N25: =$I$11+(K24*$I$18) -> 34.31
A26: =ROUND(B26,2) -> 1.19 | B26: 1.1875 | C26: 19 | E26: 4.99 | F26: =IF(B26<=3,E26,IF(B26<=20,E26+((B26-3)*$D$2),)) -> 4.99 | K26: 23 | L26: =K26*16 -> 368 | M26: =$I$10+(K25*$I$18) -> 17.97 | N26: =$I$11+(K25*$I$18) -> 34.69
A27: =ROUND(B27,2) -> 1.25 | B27: 1.25 | C27: 20 | E27: 4.99 | F27: =IF(B27<=3,E27,IF(B27<=20,E27+((B27-3)*$D$2),)) -> 4.99 | K27: 24 | L27: =K27*16 -> 384 | M27: =$I$10+(K26*$I$18) -> 18.35 | N27: =$I$11+(K26*$I$18) -> 35.07
A28: =ROUND(B28,2) -> 1.31 | B28: 1.3125 | C28: 21 | E28: 5.37 | F28: =IF(B28<=3,E28,IF(B28<=20,E28+((B28-3)*$D$2),)) -> 5.37 | K28: 25 | L28: =K28*16 -> 400 | M28: =$I$10+(K27*$I$18) -> 18.73 | N28: =$I$11+(K27*$I$18) -> 35.45
A29: =ROUND(B29,2) -> 1.38 | B29: 1.375 | C29: 22 | E29: 5.37 | F29: =IF(B29<=3,E29,IF(B29<=20,E29+((B29-3)*$D$2),)) -> 5.37 | K29: 26 | L29: =K29*16 -> 416 | M29: =$I$10+(K28*$I$18) -> 19.11 | N29: =$I$11+(K28*$I$18) -> 35.83
A30: =ROUND(B30,2) -> 1.44 | B30: 1.4375 | C30: 23 | E30: 5.37 | F30: =IF(B30<=3,E30,IF(B30<=20,E30+((B30-3)*$D$2),)) -> 5.37 | K30: 27 | L30: =K30*16 -> 432 | M30: =$I$10+(K29*$I$18) -> 19.49 | N30: =$I$11+(K29*$I$18) -> 36.21
A31: =ROUND(B31,2) -> 1.5 | B31: 1.5 | C31: 24 | E31: 5.37 | F31: =IF(B31<=3,E31,IF(B31<=20,E31+((B31-3)*$D$2),)) -> 5.37 | K31: 28 | L31: =K31*16 -> 448 | M31: =$I$10+(K30*$I$18) -> 19.87 | N31: =$I$11+(K30*$I$18) -> 36.59
A32: =ROUND(B32,2) -> 1.56 | B32: 1.5625 | C32: 25 | E32: 5.52 | F32: =IF(B32<=3,E32,IF(B32<=20,E32+((B32-3)*$D$2),)) -> 5.52 | K32: 29 | L32: =K32*16 -> 464 | M32: =$I$10+(K31*$I$18) -> 20.25 | N32: =$I$11+(K31*$I$18) -> 36.97
A33: =ROUND(B33,2) -> 1.63 | B33: 1.625 | C33: 26 | E33: 5.52 | F33: =IF(B33<=3,E33,IF(B33<=20,E33+((B33-3)*$D$2),)) -> 5.52 | K33: 30 | L33: =K33*16 -> 480 | M33: =$I$10+(K32*$I$18) -> 20.63 | N33: =$I$11+(K32*$I$18) -> 37.35
A34: =ROUND(B34,2) -> 1.69 | B34: 1.6875 | C34: 27 | E34: 5.52 | F34: =IF(B34<=3,E34,IF(B34<=20,E34+((B34-3)*$D$2),)) -> 5.52 | K34: 31 | L34: =K34*16 -> 496 | M34: =$I$10+(K33*$I$18) -> 21.01 | N34: =$I$11+(K33*$I$18) -> 37.73
A35: =ROUND(B35,2) -> 1.75 | B35: 1.75 | C35: 28 | E35: 5.52 | F35: =IF(B35<=3,E35,IF(B35<=20,E35+((B35-3)*$D$2),)) -> 5.52 | K35: 32 | L35: =K35*16 -> 512 | M35: =$I$10+(K34*$I$18) -> 21.39 | N35: =$I$11+(K34*$I$18) -> 38.11
... A53: =ROUND(B53,2) -> 2.88 | B53: 2.875 | C53: 46 | E53: 6.62 | F53: =IF(B53<=3,E53,IF(B53<=20,E53+((B53-3)*$D$2),)) -> 6.62 | K53: 50 | L53: =K53*16 -> 800 | M53: =$I$10+(K52*$I$18) -> 28.23 | N53: =$I$11+(K52*$I$18) -> 44.95
A54: =ROUND(B54,2) -> 2.94 | B54: 2.9375 | C54: 47 | E54: 6.62 | F54: =IF(B54<=3,E54,IF(B54<=20,E54+((B54-3)*$D$2),)) -> 6.62 | K54: 51 | L54: =K54*16 -> 816 | O54: 40.12
A55: =ROUND(B55,2) -> 3 | B55: 3 | C55: 48 | E55: 6.62 | F55: =IF(B55<=3,E55,IF(B55<=20,E55+((B55-3)*$D$2),)) -> 6.62 | K55: 52 | L55: =K55*16 -> 832 | O55: =IF(K54<=50,$I$11+(K54*$I$18),IF(K54<=70,$I$12+((K54-50)*$I$19),"-")) -> 40.87
A56: =ROUND(B56,2) -> 3.25 | B56: 3.25 | C56: 52 | E56: 6.92 | F56: =IF(B56<=3,E56,IF(B56<=20,E56+((B56-3)*$D$2),)) -> 7 | K56: 53 | L56: =K56*16 -> 848 | O56: =IF(K55<=50,$I$11+(K55*$I$18),IF(K55<=70,$I$12+((K55-50)*$I$19),"-")) -> 41.62
A57: =ROUND(B57,2) -> 3.5 | B57: 3.5 | C57: 56 | E57: 6.92 | F57: =IF(B57<=3,E57,IF(B57<=20,E57+((B57-3)*$D$2),)) -> 7.08 | K57: 54 | L57: =K57*16 -> 864 | O57: =IF(K56<=50,$I$11+(K56*$I$18),IF(K56<=70,$I$12+((K56-50)*$I$19),"-")) -> 42.37
...

Sheet MAIN
A1: SKU | B1: LOCATION | C1: DC LIST | D1: CAT | E1: LO-1 | F1: LO-2 | G1: AVG. SALES | H1: RANK | I1: P. COST | J1: Stock Sheet | K1: Freight-FBA | L1: Freight-Canada | M1: Freight-WFS | N1: OLD/NEW | O1: NEW SKU(IMPR.) | P1: TOP 127
A2: B10 | B2: C11-6249-B10 | D2: CFB | E2: Tushar | F2: Darshan | G2: 70 | H2: 13 | I2: 51.06 | J2: 1 | K2: -16.759967 | L2: -52.7 | N2: OLD | P2: TOP 127
A3: B10J | B3: A03-0077-B10J | D3: CFB | E3: Tushar | F3: Darshan | G3: 5 | H3: 314 | I3: 6.71 | J3: 2 | K3: -7.004 | L3: -2.4853295 | N3: OLD
A4: B10X | B4: C12-6285-B10X | D4: CFB | E4: Tushar | F4: Darshan | G4: 17 | H4: 123 | I4: 14.51 | J4: 3 | K4: -10.486876 | L4: -9.3312077 | N4: OLD | P4: TOP 127
A5: B11 | B5: C11-6256-B11 | D5: CFB | E5: Tushar | F5: Darshan | G5: 8 | H5: 108 | I5: 40.44 | J5: 4 | K5: -19.1712 | L5: -31.54 | N5: OLD
A6: B12 | B6: C11-6262-B12 | D6: CFB | E6: Tushar | F6: Darshan | G6: 14 | H6: 76 | I6: 49.59 | J6: 5 | K6: -21.690171 | L6: -38.300555 | N6: OLD | P6: TOP 127
A7: B12F | B7: A07-0273-B12F | D7: CFB | E7: Tushar | F7: Darshan | G7: 13 | H7: 119 | I7: 4.27 | J7: 6 | K7: -1.54 | L7: -3.57 | N7: OLD
A8: B12H | B8: B2-4070-B12H | D8: CFB | E8: Tushar | F8: Darshan | G8: 8 | H8: 232 | I8: 9.42 | J8: 7 | K8: -8.4795737 | L8: -8.277391 | N8: OLD
A9: B12J | B9: C12-6281-B12J | D9: CFB | E9: Tushar | F9: Darshan | G9: 7 | H9: 236 | I9: 14.72 | J9: 8 | K9: -15.036053 | L9: -12.200814 | N9: OLD
A10: B12X | B10: C4-6059-B12X | D10: CFB | E10: Tushar | F10: Darshan | G10: 22 | H10: 103 | I10: 26.98 | J10: 9 | K10: -15.760168 | L10: -7.5770381 | N10: OLD | P10: TOP 127
A11: B9J | B11: A07-0269-B9J | D11: CFB | E11: Tushar | F11: Darshan | G11: 40 | H11: 131 | I11: 3.99 | J11: 10 | K11: -6.0278534 | L11: -2.8322584 | N11: OLD | P11: TOP 127
A12: BS10 | B12: C10-6199-BS10 | D12: CFB | E12: Tushar | F12: Darshan | G12: 44 | H12: 57 | I12: 26.17 | J12: 11 | K12: -14.822188 | L12: -29.8 | N12: OLD | P12: TOP 127
A13: BS9 | B13: C12-6277-BS9 | D13: CFB | E13: Tushar | F13: Darshan | G13: 13 | H13: 157 | I13: 18.93 | J13: 12 | K13: -15.404284 | L13: -12.39 | N13: OLD | P13: TOP 127
A14: CP-1-2425F | B14: A28-1033-CP-1-2425F | D14: CP | E14: Shubham | F14: Darshan | G14: 6 | H14: 213 | I14: 19.8 | J14: 13 | K14: -6.2999778 | L14: -1.9356284 | N14: OLD | P14: TOP 127
A15: CP-2-2425F | B15: A07-0281-CP-2-2425F | D15: CP | E15: Shubham | F15: Darshan | G15: 3 | H15: 251 | I15: 37.68 | J15: 14 | K15: -2.9065608 | L15: NA | N15: OLD
A16: CP-3-2425F | B16: C12-6323-CP-3-2425F | D16: CP | E16: Shubham | F16: Darshan | G16: 3 | H16: 248 | I16: 51.7 | J16: 15 | K16: -7.745 | L16: -3.8545329 | N16: OLD | P16: TOP 127
A17: CT-AM04 | B17: A27-1021-CT-AM04 | D17: CT | E17: Ronak | F17: Darshan | G17: 42 | H17: 129 | I17: 6.07 | J17: 16 | K17: -1.4121591 | L17: -0.8 | N17: OLD | P17: TOP 127
A18: CT-AM125 | B18: B1-4023-CT-AM125 | D18: CT | E18: Ronak | F18: Darshan | G18: 13 | H18: 120 | I18: 17.17 | J18: 17 | K18: -5.2866667 | L18: NA | N18: OLD
A19: CT-AS10 | B19: B1-4029-CT-AS10 | D19: CT | E19: Ronak | F19: Darshan | G19: 9 | H19: 220 | I19: 11.91 | J19: 18 | K19: NA | L19: NA | N19: OLD
A20: CT-TC22 | B20: B5-4253-CT-TC22 | D20: CT | E20: Ronak | F20: Darshan | G20: 24 | H20: 49 | I20: 60.85 | J20: 19 | K20: -11.560109 | L20: -2.27 | N20: OLD | P20: TOP 127
A21: CT-WK22 | B21: B1-4049-CT-WK22 | C21: DC 25 | D21: CT | E21: Ronak DC | F21: DC2 | G21: 6 | H21: 134 | I21: 29.72 | J21: 20 | K21: -12.96875 | L21: NA | N21: OLD
A22: EH-03 | B22: A26-0966-EH-03 | D22: EH | E22: Tejas | F22: Darshan | G22: 12 | H22: 178 | I22: 10.52 | J22: 21 | K22: -0.5725 | L22: -0.38 | N22: OLD
A23: FP-61 | B23: A27-1023-FP-61 | D23: FP | E23: Shubham | F23: Darshan | G23: 49 | H23: 158 | I23: 3.03 | J23: 22 | K23: -0.68279167 | L23: -0.42867746 | N23: OLD | P23: TOP 127
A24: FP-64 | B24: A25-0929-FP-64 | D24: FP | E24: Shubham | F24: Darshan | G24: 8 | H24: 468 | I24: 3.03 | J24: 23 | K24: -0.47813953 | L24: NA | N24: OLD
A25: FP-68 | B25: A25-0935-FP-68 | D25: FP | E25: Shubham | F25: Darshan | G25: 80 | H25: 78 | I25: 3.03 | J25: 24 | K25: -0.56966667 | L25: -0.12 | N25: OLD
A26: FP-71 | B26: A07-0285-FP-71 | D26: FP | E26: Shubham | F26: Darshan | G26: 89 | H26: 56 | I26: 8.8 | J26: 25 | K26: -1.3845455 | L26: -1.4809243 | N26: OLD | P26: TOP 127
A27: FPB-02 | B27: A26-0980-FPB-02 | C27: SEA | D27: FPB | E27: Tejas | F27: Darshan | G27: 0 | I27: 22 | J27: 26 | K27: -3.7722222 | L27: NA | N27: OLD
A28: HB-10P | B28: C9-6161-HB-10P | D28: HB | E28: Ronak | F28: Darshan | G28: 54 | H28: 8 | I28: 39.15 | J28: 27 | K28: -6.8771632 | L28: -5.4783643 | M28: -4 | N28: OLD | P28: TOP 127
A29: HB-18 | B29: B2-4073-HB-18 | D29: HB | E29: Ronak | F29: Darshan | G29: 9 | H29: 69 | I29: 30.4 | J29: 28 | K29: -4.21 | L29: -16.651551 | N29: OLD
A30: HB-25 | B30: B2-4059-HB-25 | D30: HB | E30: Ronak | F30: Darshan | G30: 12 | H30: 67 | I30: 33.86 | J30: 29 | K30: -7.8242874 | L30: -20.125094 | N30: OLD | P30: TOP 127
A31: HB-35 | B31: B1-4031-HB-35 | D31: HB | E31: Ronak | F31: Darshan | G31: 7 | H31: 104 | I31: 46.04 | J31: 30 | K31: -10.635167 | L31: -43.190765 | N31: OLD
A32: IB-A06 | B32: C5-6071-IB-A06 | D32: IB | E32: Tushar | F32: Darshan | G32: 43 | H32: 52 | I32: 13.21 | J32: 31 | K32: -5.5303333 | L32: -3.7730392 | N32: OLD | P32: TOP 127
A33: IB-A16 | B33: D7-8026-IB-A16 | D33: IB | E33: Tushar | F33: Darshan | G33: 77 | H33: 20 | I33: 29.04 | J33: 32 | K33: -11.962972 | L33: -11.385153 | N33: OLD | P33: TOP 127
A34: IB-C05 | B34: B2-4091-IB-C05 | D34: IB | E34: Tushar | F34: Darshan | G34: 28 | H34: 63 | I34: 14.92 | J34: 33 | K34: -5.64 | L34: -3.514046 | N34: OLD | P34: TOP 127
A35: IB-C12 | B35: D6-8023-IB-C12 | C35: DC 25 | D35: IB | E35: Tushar DC | F35: DC2 | G35: 54 | H35: 30 | I35: 31.35 | J35: 34 | K35: -12.644096 | L35: -7.2306863 | M35: -6.24 | N35: OLD | P35: TOP 127
A36: IB-D10 | B36: D8-8032-IB-D10 | C36: DC 25 | D36: IB | E36: Tushar DC | F36: DC2 | G36: 10 | H36: 64 | I36: 33.55 | J36: 35 | K36: -11.815 | L36: -11.5434 | N36: OLD
A37: IB-F08 | B37: D10-8039-IB-F08 | D37: IB | E37: Tushar | F37: Darshan | G37: 22 | H37: 45 | I37: 32.14 | J37: 36 | K37: -9.4857188 | L37: -20.864074 | N37: OLD | P37: TOP 127
A38: IB-G08 | B38: D7-8028-IB-G08 | C38: DC 25 | D38: IB | E38: Tushar DC | F38: DC2 | G38: 52 | H38: 24 | I38: 41.8 | J38: 37 | K38: -8.6113379 | L38: -14.534708 | N38: OLD | P38: TOP 127
A39: JMT-02 | B39: D11-8043-JMT-02 | D39: JMT | E39: Shubham | F39: Darshan | G39: 2 | H39: 216 | I39: 127.96 | J39: 38 | K39: -23.323333 | L39: -31.465189 | N39: OLD | P39: TOP 127
A40: JMT-03 | B40: D6-8021-JMT-03 | D40: JMT | E40: Shubham | F40: Darshan | G40: 4 | H40: 44 | I40: 160.06 | J40: 39 | K40: -21.772033 | L40: -39.025253 | N40: OLD | P40: TOP 127
...

Sheet State
A1: Row Labels | B1: Real State | C1: Remarks
A2: AA | B2: AA
A3: AB | B3: AB
A4: AE | B4: AE
A5: Aguascalientes | B5: AG
A6: AK | B6: AK
A7: AL | B7: AL
A8: ALABAMA | B8: AL
A9: Alaska | B9: AK
A10: Alberta | B10: AB
A11: Antioquia | B11: CO-ANT
A12: AP | B12: AP
A13: AR | B13: AR
... A19: BC | B19: BC
A20: Bogotá | B20: 0
A21: Bolívar | B21: 0
A22: British Columbia | B22: BC
A23: CA | B23: CA
A24: Ca. | B24: CA
A25: Cali | B25: CA
A26: CALIFORNIA | B26: CA
A27: CHIAPAS | B27: CS
A28: CO | B28: CO
A29: Colorado | B29: CO
A30: Connecticut | B30: CT
A31: Ct | B31: CT
A32: DC | B32: DC
A33: DE | B33: DE
... A39: GEORGIA | B39: GA
A40: Girón | B40: 0
A41: GU | B41: GU
A42: GUANAJUATO | B42: GJ
A43: HAWAII | B43: HI
A44: HI | B44: HI
A45: HIDALGO | B45: HD
A46: IA | B46: IA
A47: ID | B47: ID
A48: Idaho | B48: ID
A49: IL | B49: IL
A50: ILLINOIS | B50: IL
...

Sheet ALL SKU
A1: Row Labels | B1: SKU WITH BRACKET
A2: 00001Q01T | B2: CB-S1
A3: 00002Q01T | B3: CB-S2
A4: 00003Q01T | B4: CB-Z1
A5: 00004Q01T | B5: CB-Z2
A6: 00005Q01A | B6: CR-1
A7: 00006Q01A | B7: CR-2
A8: 00007Q01A | B8: CR-3
A9: 00008Q01A | B9: CR-4
A10: 00009Q01T | B10: B10J
A11: 00010Q01T | B11: B10X
A12: 00011Q01P | B12: B11
... A11975: FAB-432 + FAB-435 (HB) | B11975: FAB-432+FAB-435

Sheet Listing Price
A1: Row Labels | B1: No | C1: 5% discount | D1: Lower Price Limit
A2: B10 | B2: 1 | C2: 112.2926 | D2: 112.29
A3: B10J | B3: 2 | C3: 31.350059 | D3: 31.35
A4: B10X | B4: 3 | C4: 58.91674 | D4: 58.92
A5: B11 | B5: 4 | C5: 103.29737 | D5: 103.3
A6: B12 | B6: 5 | C6: 128.31234 | D6: 128.31
A7: B12F | B7: 6 | C7: 24.379923 | D7: 24.38
A8: B12H | B8: 7 | C8: 38.220803 | D8: 38.22
A9: B12J | B9: 8 | C9: 51.414559 | D9: 51.41
A10: B12X | B10: 9 | C10: 75.953353 | D10: 75.95
A11: B9J | B11: 10 | C11: 24.864766 | D11: 24.86
A12: BS10 | B12: 11 | C12: 82.755802 | D12: 82.76
A13: BS13 | B13: 12 | C13: 84.0405 | D13: 84.04
... A479: RCB-13 | B479: 740 | C479: 21.499556 | D479: 21.5
A480: UPF-POT | B480: NA | C480: 59.375 | D480: 59.38
A481: JMT-120 | B481: NA | C481: 23.845 | D481: 23.85
A482: JMT-91 | B482: NA | C482: 20.00519 | D482: 20.01
A483: UPFR-10 | B483: NA | C483: 30.1853 | D483: 30.19
A484: UFAB-94 | B484: NA | C484: 47.9655 | D484: 47.97
A485: UPO-AC2 | B485: NA | C485: 51.7655 | D485: 51.77
A486: UFAB-339 | B486: NA | C486: 30.4855 | D486: 30.49
A487: BA-H05 | B487: NA | C487: 15.6655 | D487: 15.67
A488: FAB-36 | B488: NA | C488: 37.8955 | D488: 37.9
A489: JMT-116 | B489: NA | C489: 33.7155 | D489: 33.72
A490: PF-10 | B490: NA | C490: 69.8155 | D490: 69.82
A491: UPFI-O10 | B491: NA | C491: 40.736 | D491: 40.74
... A675: UJMT-59 | B675: NA | C675: 54.8948 | D675: 54.89
A676: CR-3 | B676: 20 | C676: 0 | D676: 0
A677: CR-G1510 | B677: 21 | C677: 0 | D677: 0
A678: CR-G1905 | B678: 22 | C678: 0 | D678: 0
A679: CR-G2505 | B679: 23 | C679: 0 | D679: 0
A680: CR-G5005 | B680: 24 | C680: 0 | D680: 0
A681: FB-0303 | B681: 33 | C681: 0 | D681: 0
A682: FP-66 | B682: 37 | C682: 0 | D682: 0
A683: FP-69 | B683: 39 | C683: 0 | D683: 0
A684: FPB-01 | B684: 44 | C684: 0 | D684: 0
A685: FPB-02 | B685: 45 | C685: 0 | D685: 0
A686: FPB-03 | B686: 46 | C686: 0 | D686: 0
A687: GT-12 | B687: 47 | C687: 0 | D687: 0
... A945: ARPZ007 | B945: 748 | C945: 0 | D945: 0

Sheet CALCULATOR MAIN
F4: FBA FEES CALCULATOR | O4: Removal Fees Calculator | W4: Liquidation Fees
W5: Weight (lb) | X5: Processing Fee ($)
G6: Enter Values | J6: Tier | P6: Enter Values | S6: Tier | T6: Size Tier | W6: ='[1]Main Sheet'!D6 -> 29 | X6: =IF(W6<=0.5, 0.25, IF(W6<=1, 0.3, IF(W6<=2, 0.35, IF(W6>2, 0.4 + 0.2 * (W6 - 2), "")))) -> 5.8
G7: Weight(oz) | H7: =M12*16 -> 464 | P7: Weight(oz) | Q7: =#REF!*16 -> #REF!
G8: Longest | H8: 61 | J8: Small standard-size | M8: Tier | P8: Tier | Q8: =VLOOKUP($M$9,'[1]REMOVAL FEES'!$K$1:$L$7,2,FALSE) -> 2 | S8: 1 | T8: Small standard-size
G9: Median | H9: 9 | J9: Large standard-size | M9: =IF(AND($M$12<=J50,$H$8<=G50,$H$9<=H50,$H$10<=I50),A50,IF(AND($M$12<=J51,$H$8<=G51,$H$9<=H51,$H$10<=I51),A51,IF(AND($H$8<=G52,$H$9<=H52,$H$10<=I52,$M$12<=J52),A52,IF(AND($M$12<=J53,OR(H$8>G53,$H$9>H53,$H$10>I53)),A53,IF(AND($M$12>J53,$M$12<=J54),A54,IF(AND($M$12>J54,$M$12<=J55),A55,A56)))))) -> Extra-large 0 to 50 lb | P9: Weight (lb) | Q9: =M12 -> 29 | T9: Large standard-size
G10: Shortest | H10: 6 | J10: Large bulky | M10: Fees | P10: Qty | Q10: 1 | S10: 2 | T10: Large bulky
G11: Weight(lbs) | H11: ='[1]Main Sheet'!D6 -> 29 | J11: Extra-large 0 to 50 lb | M11: =IFERROR(VLOOKUP(ROUNDUP($H$7,0),'FBA FEES'!$L$2:$Q$203,MATCH(M9,'FBA FEES'!$L$2:$Q$2,0),FALSE),VLOOKUP(ROUNDUP($H$7,0),'FBA FEES'!$C$6:$F$123,MATCH(M9,'FBA FEES'!$C$6:$F$6,0),FALSE)) -> 36.97 | T11: Extra-large 0 to 50 lb
G12: Diemensional Weight (lb) | H12: =(H8*H9*H10)/139 -> 23.697842 | J12: Extra-large 50+ to 70 lb | M12: =ROUND(MAX($H$11,$H$12),0) -> 29 | P12: Tier | Q12: ='[1]REMOVAL CHART'!$B$20 -> Large bulky, extra-large and special handling items | T12: Extra-large 50+ to 70 lb | W12: Grade and Resell Fees
J13: Extra-large 70+ to 150 lb | P13: Fees | Q13: ='[1]REMOVAL CHART'!$B$21 -> 15.38 | T13: Extra-large 70+ to 150 lb | W13: Price ($) | X13: Weight (lb) | Y13: Amazon Fee ($) | Z13: Profit ($)
G14: =M10 -> Fees | H14: =M11 -> 36.97 | J14: Extra-large 150+ lb | T14: Extra-large 150+ lb | W14: ='[1]Main Sheet'!J6 -> 12 | X14: ='[1]Main Sheet'!D6 -> 29 | Y14: =IF(X14<=1, 1.5, IF(X14<=21, 1.8, IF(X14<=151, 2.65, 4.1))) -> 2.65 | Z14: =W14-Y14 -> 9.35
M17: =IF(AND($H10<=J50,$A10<=G50,$F10<=H50,$G10<=I50),A50,IF(AND($H10<=J51,$A10<=G51,$F10<=H51,$G10<=I51),A51,IF(AND($A10<=G52,$F10<=H52,$G10<=I52,$H10<=J52),A52,IF(AND($H10<=J53,OR($A10>G53,$F10>H53,$G10>I53)),A53,IF(AND($H10>J53,$H10<=J54),A54,IF(AND($H10>J54,$H10<=J55),A55,A56)))))) -> Extra-large 0 to 50 lb
M18: =IFERROR(VLOOKUP(ROUNDUP($H$7,0),'FBA FEES'!$L$2:$Q$203,MATCH(M9,'FBA FEES'!$L$2:$Q$2,0),FALSE),VLOOKUP(ROUNDUP($H$7,0),'FBA FEES'!$C$6:$F$123,MATCH(M9,'FBA FEES'!$C$6:$F$6,0),FALSE)) -> 36.97
M19: =IF(AND($M$12<=J50,$H$8<=G50,$H$9<=H50,$H$10<=I50),A50,IF(AND($M$12<=J51,$H$8<=G51,$H$9<=H51,$H$10<=I51),A51,IF(AND($H$8<=G52,$H$9<=H52,$H$10<=I52,$M$12<=J52),A52,IF(AND($M$12<=J53,OR(H$8>G53,$H$9>H53,$H$10>I53)),A53,IF(AND($M$12>J53,$M$12<=J54),A54,IF(AND($M$12>J54,$M$12<=J55),A55,A56)))))) -> Extra-large 0 to 50 lb
P23: Length + girth | Q23: Weight
A24: Shipping weight1 | F24: Longest side | G24: Median side | H24: Shortest side | I24: Length + girth | J24: Product size tier | L24: Shipping weight1 | M24: Longest side | N24: Median side | O24: Shortest side | Q24: 1
A25: Up to 16 oz | F25: Up to 15 inches | G25: Up to 12 inches | H25: Up to 0.75 inch | I25: n/a | J25: Small standard-size | K25: 1 | L25: Up to 16 oz | M25: 15 | N25: 12 | O25: 0.75 | Q25: 20
A26: Up to 20 lb | F26: Up to 18 inches | G26: Up to 14 inches | H26: Up to 8 inches | I26: n/a | J26: Large standard-size | K26: 2 | L26: Up to 20 lb | M26: 18 | N26: 14 | O26: 8 | S26: Size tier | U26: Shipping weight | V26: Removal fee per unit
A27: Up to 50 lb | F27: Up to 59 inches | G27: Up to 33 inches | H27: Up to 33 inches | I27: Up to 130 inches | J27: LARGE | K27: 3 | S27: Standard size | T27: Small standard-size | U27: 0 to 0.5 lb | V27: $1.04
A28: Up to 50 lb | F28: Extra-large exceeds 59 inches for the longest side or 33 inches for the median side or 33 inches for the shortest side or 130 inches for length + girth, or if the product’s greater of unit weight or dimensional weight exceeds 50 lb. | O28: =IF(AND(H8<=M25,H11<=Q24),K25,IF(AND(H8<=M26,H11>Q24,H11<=Q25),K26,J27)) -> LARGE | U28: 0.5+ to 1.0 lb | V28: $1.53 | X28: SIZE | Y28: Tier | Z28: Longest side | AA28: Median side | AB28: Shortest side | AC28: Weight
A29: 50+ to 70 lb | O29: =IF(H9<=N25,K25,IF(H9<=N26,K26,IF(H9<=N42,K42,IF(H9>N43,K43,IF(H9>N44,K44,IF(H9>N45,K45,IF(H9>N46,K46))))))) -> 1 | T29: Large standard-size | U29: 1.0+ to 2.0 lb | V29: $2.27 | X29: Small standard-size | Y29: 1 | Z29: 15 | AA29: 12 | AB29: 0.75 | AC29: 1
A30: 70+ to 150 lb | O30: =IF(H10<=O25,K25,IF(H10<=O26,K26,IF(H10<=O42,K42,IF(H10>O43,K43,IF(H10>O44,K44,IF(H10>O45,K45,IF(H10>O46,K46))))))) -> 2 | U30: More than 2 lb | V30: $2.89 + $1.06/lb above 2 lb | X30: Large standard-size | Y30: 2 | Z30: 18 | AA30: 14 | AB30: 8 | AC30: 20
A31: Over 150 lb | O31: =IF(H11<=Q24,K25,IF(H11<=Q25,K26,IF(H11<=Q41,K42,IF(H11<=Q42,K43,IF(AND(H11>=Q43,H11>Q42),K44,IF(H11>Q44,K45,IF(H11>Q45,K46))))))) -> 3 | S31: Large bulky, extra-large and special handling items | T31: Large bulky | U31: 0 to 1.0 lb | V31: $3.12 | X31: Large bulky | Y31: 3 | Z31: 59 | AA31: 33 | AB31: 33 | AC31: 50
L32: Weight(oz) | M32: =H11*16 -> 464 | T32: Extra-large 0 to 50 lb | U32: 1.0+ to 2.0 lb | V32: $4.30 | X32: Extra-large 0 to 50 lb | Y32: 4 | Z32: 59 | AA32: 33 | AB32: 33 | AC32: 50
T33: Extra-large 50+ to 70 lb | U33: 2.0+ to 4.0 lb | V33: $6.36 | X33: Extra-large 50+ to 70 lb | Y33: 5 | Z33: 59 | AA33: 33 | AB33: 33 | AC33: 70
T34: Extra-large 70+ to 150 lb | U34: 4.0+ to 10.0 lb | V34: $10.04 | X34: Extra-large 70+ to 150 lb | Y34: 6 | Z34: 59 | AA34: 33 | AB34: 33 | AC34: 150
J35: LARGE | T35: Extra-large 150+ lb | U35: More than 10.0 lb | V35: $14.32 + $1.06/lb above 10 lb | X35: Extra-large 150+ lb | Y35: 7 | Z35: 59 | AA35: 33 | AB35: 33 | AC35: 150.1
P41: Up to 130 inches | Q41: 50 | S41: Tier | T41: =[1]CALCULATOR!AA33 -> 0 | U41: =T41 -> 0
J42: Large bulky | K42: 3 | L42: Up to 50 lb | M42: 59 | N42: 33 | O42: 33 | Q42: 50.1 | S42: Weight | T42: =[1]CALCULATOR!AA34 -> 0 | U42: =IF(AND($F$17>0,$F$17<=0.5),0.5,ROUND($F$17,0)) -> 0
J43: Extra-large 0 to 50 lb | K43: 4 | L43: Up to 50 lb | M43: 59 | N43: 33 | O43: 33 | Q43: 70 | S43: Qty | T43: =[1]CALCULATOR!AA35 -> 0 | U43: =T43 -> 0
J44: Extra-large 50+ to 70 lb | K44: 5 | L44: 50+ to 70 lb | M44: 59 | N44: 33 | O44: 33 | Q44: 150
J45: Extra-large 70+ to 150 lb | K45: 6 | L45: 70+ to 150 lb | M45: 59 | N45: 33 | O45: 33 | Q45: 150.1 | S45: Tier | T45: =IF($F$16=1,$A$2,IF($F$16=2,$A$6)) -> FALSE
J46: Extra-large 150+ lb | K46: 7 | L46: Over 150 lb | M46: 59 | N46: 33 | O46: 33 | S46: Fees | T46: =IFERROR(IF($G$16=1,$G$24,IF($G$16=2,IF($G$17>10,(($G$17-10)*1.06)+$G$25,$G$25)))*$G$18,FALSE) -> 0
T48: =IF(AND(P73<=0.25,$S73="Small standard-size"),"Small standard: 4 oz or less") -> FALSE
A49: SIZE | F49: Tier | G49: Longest side | H49: Median side | I49: Shortest side | J49: Weight | Q49: =IF(COUNTIF(L50:O50,TRUE)=4,F50,"-") -> -
A50: Small standard-size | F50: 1 | G50: 15 | H50: 12 | I50: 0.75 | J50: 1 | L50: =$H$8<=G50 -> FALSE | M50: =$H$9<=H50 -> TRUE | N50: =$H$10<=I50 -> FALSE | O50: =$H$11<=J50 -> FALSE | Q50: =IF(COUNTIF(L51:O51,TRUE)=4,F51,"-") -> -
A51: Large standard-size | F51: 2 | G51: 18 | H51: 14 | I51: 8 | J51: 20 | L51: =$H$8<=G51 -> FALSE | M51: =$H$9<=H51 -> TRUE | N51: =$H$10<=I51 -> TRUE | O51: =AND($H$11<=J51,$H$11>J50) -> FALSE | Q51: =IF(COUNTIF(L52:O52,TRUE)=4,F52,"-") -> -
A52: Large bulky | F52: 3 | G52: 59 | H52: 33 | I52: 33 | J52: 50 | L52: =$H$8<=G52 -> FALSE | M52: =$H$9<=H52 -> TRUE | N52: =$H$10<=I52 -> TRUE | O52: =AND($H$11<=J52,$H$11>J51) -> TRUE | Q52: =IF(COUNTIF(L53:O53,TRUE)=4,F53,"-") -> -
A53: Extra-large 0 to 50 lb | F53: 4 | G53: 59 | H53: 33 | I53: 33 | J53: 50 | L53: =$H$8<=G53 -> FALSE | M53: =$H$9<=H53 -> TRUE | N53: =$H$10<=I53 -> TRUE | O53: =AND($H$11<=J53,$H$11>J52) -> FALSE | Q53: =IF(COUNTIF(L54:O54,TRUE)=4,F54,"-") -> -
A54: Extra-large 50+ to 70 lb | F54: 5 | G54: 59 | H54: 33 | I54: 33 | J54: 70 | L54: =$H$8<=G54 -> FALSE | M54: =$H$9<=H54 -> TRUE | N54: =$H$10<=I54 -> TRUE | O54: =AND($H$11<=J54,$H$11>J53) -> FALSE | Q54: =IF(COUNTIF(L55:O55,TRUE)=4,F55,"-") -> -
...

Sheet Stores
A1: STORE | B1: SHORT
A2: Amazon Califonia | B2: A-CA
A3: Amazon Hytech | B3: A-HY
A4: Amazon Silion | B4: A-SL
A5: Amazon SimondStore | B5: A-SS
A6: EBAY CALIFONIA | B6: E-CA
A7: Ebay Hytech | B7: E-HY
A8: Ebay Simondstore | B8: E-SS
A9: Walmart Store | B9: WALMART
A10: Amazon Hytech - FBA | B10: A-HY
A11: Amazon Silion - FBA | B11: A-SL
A12: Amazon Canada - FBA | B12: A-CAN
... A20: Amazon Silion Mexico - FBA | B20: A-SL(MX)

Sheet FREIGHT BACKUP
B1: 45627
A2: SKU | B2: Freight-FBA | C2: Freight-Canada
A3: B10 | B3: -16.759967 | C3: -52.7
A4: B10J | B4: -7.004 | C4: -2.4853295
A5: B10X | B5: -8.57825 | C5: -9.3312077
A6: B11 | B6: -16.317833 | C6: -31.54
A7: B12 | B7: -19.018656 | C7: -38.300555
A8: B12F | B8: -1.554 | C8: -3.57
A9: B12H | B9: -7.3943852 | C9: -8.277391
A10: B12J | B10: -4.75 | C10: -12.200814
A11: B12X | B11: -13.209306 | C11: -7.5770381
A12: B9J | B12: -6.2852985 | C12: -2.8322584
A13: BS10 | B13: -13.158981 | C13: -29.8
A14: BS13 | B14: -9.872619 | C14: -6.63
A15: BS9 | B15: -8.4990151 | C15: -12.39
A16: CM-B209 | B16: NA | C16: NA
A17: CP-1-2425F | B17: -6.0722035 | C17: -1.9356284
A18: CP-2-2425F | B18: -6.2123333 | C18: NA
A19: CP-3-2425F | B19: -7.1414359 | C19: -3.8545329
A20: CT-AM04 | B20: -1.3919848 | C20: -0.8
A21: CT-AM125 | B21: -4.87 | C21: NA
A22: CT-AS10 | B22: NA | C22: NA
A23: CT-TC22 | B23: -11.527667 | C23: -1.9868576
A24: CT-WK22 | B24: -11.998333 | C24: NA
A25: EH-03 | B25: -0.67 | C25: -0.38
A26: FB-0303 | B26: NA | C26: NA
A27: FP-61 | B27: -0.62086688 | C27: -0.42867746
A28: FP-64 | B28: -0.56860465 | C28: NA
A29: FP-66 | B29: NA | C29: NA
A30: FP-68 | B30: -0.61014815 | C30: -0.12
A31: FP-69 | B31: NA | C31: NA
A32: FP-70 | B32: -1.9028571 | C32: NA
A33: FP-71 | B33: -1.3831818 | C33: -1.4809243
A34: FP-72 | B34: -3.06375 | C34: NA
A35: FP-73 | B35: -11.911917 | C35: NA
A36: FPB-01 | B36: -11.719702 | C36: -3.8763852
A37: FPB-02 | B37: -3.7722222 | C37: NA
A38: FPB-03 | B38: -11.131111 | C38: -4.5323888
A39: GT-12 | B39: NA | C39: NA
A40: HB-10P | B40: -6.351224 | C40: -5.4783643
...
